Workbook

Sheet Day1 28.09.2026
A1: Order ID | B1: Customer ID | C1: Order Date | D1: Ship Date | E1: City | F1: State | G1: Sales Channel | H1: Payment Method | I1: Product Category | J1: Product Name | K1: Brand | L1: Units Sold | M1: Unit Price | N1: Discount % | O1: Net Sales | P1: Total Price | Q1: Sale Status uses of IF | R1: Sale Status1 uses of IFS | S1: Sale Status2 uses of NESTED IF
A2: 10001 | B2: 1102 | C2: 45197 | D2: 45203 | E2: Chennai | F2: Delhi | G2: Mobile App | H2: Credit Card | I2: Home & Kitchen | J2: Mixer Grinder | K2: BrandA | L2: 7 | M2: 2843.87 | N2: 0 | O2: 19907.09 | P2: =L2*M2 -> 19907.09 | Q2: =IF(O2>=15000,"high","low") -> high | R2: {=_xlfn.IFS(O2>=20000,"high",O2>=15000,"medium",O2<15000,"low")} -> medium | S2: =IF(O2>=20000,"high",IF(O2>=15000,"mid","low")) -> mid
A3: 10002 | B3: 1435 | C3: 45199 | D3: 45203 | E3: Pune | F3: Tamil Nadu | G3: Website | H3: Debit Card | I3: Sports | J3: Football | K3: BrandD | L3: 9 | M3: 2525.23 | N3: 5 | O3: 21590.72 | P3: =L3*M3 -> 22727.07 | Q3: =IF(O3>=15000,"high","low") -> high | R3: {=_xlfn.IFS(O3>=20000,"high",O3>=15000,"medium",O3<15000,"low")} -> high | S3: =IF(O3>=20000,"high",IF(O3>=15000,"mid","low")) -> high | U3: COUNT
A4: 10003 | B4: 1860 | C4: 45109 | D4: 45114 | E4: Chennai | F4: West Bengal | G4: Marketplace | H4: Debit Card | I4: Fashion | J4: Sneakers | K4: BrandE | L4: 6 | M4: 3474.34 | N4: 15 | O4: 17719.13 | P4: =L4*M4 -> 20846.04 | Q4: =IF(O4>=15000,"high","low") -> high | R4: {=_xlfn.IFS(O4>=20000,"high",O4>=15000,"medium",O4<15000,"low")} -> medium | S4: =IF(O4>=20000,"high",IF(O4>=15000,"mid","low")) -> mid
A5: 10004 | B5: 1270 | C5: 45079 | D5: 45087 | E5: Bengaluru | F5: West Bengal | G5: Website | H5: Cash on Delivery | I5: Sports | J5: Yoga Mat | K5: BrandA | L5: 1 | M5: 1008.79 | N5: 15 | O5: 857.47 | P5: =L5*M5 -> 1008.79 | Q5: =IF(O5>=15000,"high","low") -> low | R5: {=_xlfn.IFS(O5>=20000,"high",O5>=15000,"medium",O5<15000,"low")} -> low | S5: =IF(O5>=20000,"high",IF(O5>=15000,"mid","low")) -> low
A6: 10005 | B6: 1106 | C6: 45241 | D6: 45244 | E6: Kolkata | F6: Karnataka | G6: Marketplace | H6: Credit Card | I6: Fashion | J6: Jacket | K6: BrandA | L6: 7 | M6: 3511.47 | N6: 20 | O6: 19664.23 | P6: =L6*M6 -> 24580.29 | Q6: =IF(O6>=15000,"high","low") -> high | R6: {=_xlfn.IFS(O6>=20000,"high",O6>=15000,"medium",O6<15000,"low")} -> medium | S6: =IF(O6>=20000,"high",IF(O6>=15000,"mid","low")) -> mid
A7: 10006 | B7: 1071 | C7: 45260 | D7: 45263 | E7: Hyderabad | F7: Telangana | G7: Website | H7: Net Banking | I7: Home & Kitchen | J7: Bedsheet | K7: BrandE | L7: 3 | M7: 3189.55 | N7: 10 | O7: 8611.78 | P7: =L7*M7 -> 9568.65 | Q7: =IF(O7>=15000,"high","low") -> low | R7: {=_xlfn.IFS(O7>=20000,"high",O7>=15000,"medium",O7<15000,"low")} -> low | S7: =IF(O7>=20000,"high",IF(O7>=15000,"mid","low")) -> low | U7: COUNTA
A8: 10007 | B8: 1700 | C8: 45050 | D8: 45054 | E8: Bengaluru | F8: Telangana | G8: Mobile App | H8: UPI | I8: Fashion | J8: Sneakers | K8: BrandC | L8: 5 | M8: 3030.42 | N8: 10 | O8: 13636.89 | P8: =L8*M8 -> 15152.1 | Q8: =IF(O8>=15000,"high","low") -> low | R8: {=_xlfn.IFS(O8>=20000,"high",O8>=15000,"medium",O8<15000,"low")} -> low | S8: =IF(O8>=20000,"high",IF(O8>=15000,"mid","low")) -> low
A9: 10008 | B9: 1020 | C9: 45040 | D9: 45041 | E9: Mumbai | F9: Delhi | G9: Website | H9: Credit Card | I9: Fashion | J9: Sneakers | K9: BrandB | L9: 4 | M9: 2310.83 | N9: 10 | O9: 8318.99 | P9: =L9*M9 -> 9243.32 | Q9: =IF(O9>=15000,"high","low") -> low | R9: {=_xlfn.IFS(O9>=20000,"high",O9>=15000,"medium",O9<15000,"low")} -> low | S9: =IF(O9>=20000,"high",IF(O9>=15000,"mid","low")) -> low
A10: 10009 | B10: 1614 | C10: 45204 | D10: 45213 | E10: Chennai | F10: West Bengal | G10: Website | H10: Debit Card | I10: Fashion | J10: T-Shirt | K10: BrandD | L10: 5 | M10: 1098.04 | N10: 15 | O10: 4666.67 | P10: =L10*M10 -> 5490.2 | Q10: =IF(O10>=15000,"high","low") -> low | R10: {=_xlfn.IFS(O10>=20000,"high",O10>=15000,"medium",O10<15000,"low")} -> low | S10: =IF(O10>=20000,"high",IF(O10>=15000,"mid","low")) -> low
A11: 10010 | B11: 1121 | C11: 45139 | D11: 45147 | E11: Bengaluru | F11: Karnataka | G11: Website | H11: Cash on Delivery | I11: Electronics | J11: Headphones | K11: BrandB | L11: 5 | M11: 1780.66 | N11: 20 | O11: 7122.64 | P11: =L11*M11 -> 8903.3 | Q11: =IF(O11>=15000,"high","low") -> low | R11: {=_xlfn.IFS(O11>=20000,"high",O11>=15000,"medium",O11<15000,"low")} -> low | S11: =IF(O11>=20000,"high",IF(O11>=15000,"mid","low")) -> low | U11: COUNTBLANK
A12: 10011 | B12: 1466 | C12: 45098 | D12: 45106 | E12: Bengaluru | F12: Karnataka | G12: Mobile App | H12: Cash on Delivery | I12: Electronics | J12: Headphones | K12: BrandE | L12: 6 | M12: 3205.25 | N12: 0 | O12: 19231.5 | P12: =L12*M12 -> 19231.5 | Q12: =IF(O12>=15000,"high","low") -> high | R12: {=_xlfn.IFS(O12>=20000,"high",O12>=15000,"medium",O12<15000,"low")} -> medium | S12: =IF(O12>=20000,"high",IF(O12>=15000,"mid","low")) -> mid
A13: 10012 | B13: 1214 | C13: 45214 | D13: 45220 | E13: Mumbai | F13: Tamil Nadu | G13: Website | H13: UPI | I13: Electronics | J13: Smartwatch | K13: BrandA | L13: 6 | M13: 272.35 | N13: 5 | O13: 1552.39 | P13: =L13*M13 -> 1634.1 | Q13: =IF(O13>=15000,"high","low") -> low | R13: {=_xlfn.IFS(O13>=20000,"high",O13>=15000,"medium",O13<15000,"low")} -> low | S13: =IF(O13>=20000,"high",IF(O13>=15000,"mid","low")) -> low
A14: 10013 | B14: 1330 | C14: 45100 | D14: 45107 | E14: Delhi | F14: Tamil Nadu | G14: Mobile App | H14: Cash on Delivery | I14: Home & Kitchen | J14: Bedsheet | K14: BrandA | L14: 8 | M14: 3160.9 | N14: 0 | O14: 25287.2 | P14: =L14*M14 -> 25287.2 | Q14: =IF(O14>=15000,"high","low") -> high | R14: {=_xlfn.IFS(O14>=20000,"high",O14>=15000,"medium",O14<15000,"low")} -> high | S14: =IF(O14>=20000,"high",IF(O14>=15000,"mid","low")) -> high
A15: 10014 | B15: 1458 | C15: 45039 | D15: 45045 | E15: Kolkata | F15: Karnataka | G15: Marketplace | H15: Cash on Delivery | I15: Sports | J15: Yoga Mat | K15: BrandD | L15: 8 | M15: 1074.27 | N15: 15 | O15: 7305.04 | P15: =L15*M15 -> 8594.16 | Q15: =IF(O15>=15000,"high","low") -> low | R15: {=_xlfn.IFS(O15>=20000,"high",O15>=15000,"medium",O15<15000,"low")} -> low | S15: =IF(O15>=20000,"high",IF(O15>=15000,"mid","low")) -> low
A16: 10015 | B16: 1087 | C16: 45048 | D16: 45057 | E16: Hyderabad | F16: Tamil Nadu | G16: Website | H16: Credit Card | I16: Beauty | J16: Shampoo | K16: BrandA | L16: 9 | M16: 705.59 | N16: 10 | O16: 5715.28 | P16: =L16*M16 -> 6350.31 | Q16: =IF(O16>=15000,"high","low") -> low | R16: {=_xlfn.IFS(O16>=20000,"high",O16>=15000,"medium",O16<15000,"low")} -> low | S16: =IF(O16>=20000,"high",IF(O16>=15000,"mid","low")) -> low
A17: 10016 | B17: 1372 | C17: 44958 | D17: 44961 | E17: Pune | F17: West Bengal | G17: Mobile App | H17: Net Banking | I17: Fashion | J17: Jacket | K17: BrandA | L17: 8 | M17: 595.45 | N17: 5 | O17: 4525.42 | P17: =L17*M17 -> 4763.6 | Q17: =IF(O17>=15000,"high","low") -> low | R17: {=_xlfn.IFS(O17>=20000,"high",O17>=15000,"medium",O17<15000,"low")} -> low | S17: =IF(O17>=20000,"high",IF(O17>=15000,"mid","low")) -> low
A18: 10017 | B18: 1099 | C18: 45148 | D18: 45151 | E18: Delhi | F18: Maharashtra | G18: Mobile App | H18: UPI | I18: Fashion | J18: Jacket | K18: BrandD | L18: 2 | M18: 254.91 | N18: 15 | O18: 433.35 | P18: =L18*M18 -> 509.82 | Q18: =IF(O18>=15000,"high","low") -> low | R18: {=_xlfn.IFS(O18>=20000,"high",O18>=15000,"medium",O18<15000,"low")} -> low | S18: =IF(O18>=20000,"high",IF(O18>=15000,"mid","low")) -> low
A19: 10018 | B19: 1871 | C19: 45045 | D19: 45048 | E19: Chennai | F19: West Bengal | G19: Website | H19: Credit Card | I19: Home & Kitchen | J19: Curtains | K19: BrandD | L19: 1 | M19: 2165.81 | N19: 15 | O19: 1840.94 | P19: =L19*M19 -> 2165.81 | Q19: =IF(O19>=15000,"high","low") -> low | R19: {=_xlfn.IFS(O19>=20000,"high",O19>=15000,"medium",O19<15000,"low")} -> low | S19: =IF(O19>=20000,"high",IF(O19>=15000,"mid","low")) -> low
A20: 10019 | B20: 1663 | C20: 44965 | D20: 44968 | E20: Bengaluru | F20: Karnataka | G20: Marketplace | H20: Net Banking | I20: Fashion | J20: Jacket | K20: BrandE | L20: 2 | M20: 990.3 | N20: 15 | O20: 1683.51 | P20: =L20*M20 -> 1980.6 | Q20: =IF(O20>=15000,"high","low") -> low | R20: {=_xlfn.IFS(O20>=20000,"high",O20>=15000,"medium",O20<15000,"low")} -> low | S20: =IF(O20>=20000,"high",IF(O20>=15000,"mid","low")) -> low
A21: 10020 | B21: 1130 | C21: 45194 | D21: 45203 | E21: Mumbai | F21: Karnataka | G21: Mobile App | H21: Credit Card | I21: Electronics | J21: Smartwatch | K21: BrandA | L21: 2 | M21: 3959.31 | N21: 5 | O21: 7522.69 | P21: =L21*M21 -> 7918.62 | Q21: =IF(O21>=15000,"high","low") -> low | R21: {=_xlfn.IFS(O21>=20000,"high",O21>=15000,"medium",O21<15000,"low")} -> low | S21: =IF(O21>=20000,"high",IF(O21>=15000,"mid","low")) -> low
A22: 10021 | B22: 1661 | C22: 45159 | D22: 45163 | E22: Mumbai | F22: West Bengal | G22: Website | H22: Credit Card | I22: Beauty | J22: Lipstick | K22: BrandA | L22: 3 | M22: 2361.58 | N22: 5 | O22: 6730.5 | P22: =L22*M22 -> 7084.74 | Q22: =IF(O22>=15000,"high","low") -> low | R22: {=_xlfn.IFS(O22>=20000,"high",O22>=15000,"medium",O22<15000,"low")} -> low | S22: =IF(O22>=20000,"high",IF(O22>=15000,"mid","low")) -> low
A23: 10022 | B23: 1308 | C23: 44944 | D23: 44951 | E23: Kolkata | F23: Tamil Nadu | G23: Marketplace | H23: Cash on Delivery | I23: Books | J23: Fiction Novel | K23: BrandE | L23: 7 | M23: 680.86 | N23: 20 | O23: 3812.82 | P23: =L23*M23 -> 4766.02 | Q23: =IF(O23>=15000,"high","low") -> low | R23: {=_xlfn.IFS(O23>=20000,"high",O23>=15000,"medium",O23<15000,"low")} -> low | S23: =IF(O23>=20000,"high",IF(O23>=15000,"mid","low")) -> low
... A501: 10500 | B501: 1569 | C501: 44972 | D501: 44977 | E501: Chennai | F501: Delhi | G501: Marketplace | H501: Net Banking | I501: Fashion | J501: Jeans | K501: BrandE | L501: 1 | M501: 2432.17 | N501: 20 | O501: 1945.74 | P501: =L501*M501 -> 2432.17 | Q501: =IF(O501>=15000,"high","low") -> low | R501: {=_xlfn.IFS(O501>=20000,"high",O501>=15000,"medium",O501<15000,"low")} -> low | S501: =IF(O501>=20000,"high",IF(O501>=15000,"mid","low")) -> low

Sheet Day2 29.09.2026
A1: Order ID | B1: Customer ID | C1: Order Date | D1: Ship Date | E1: City | F1: State | G1: Sales Channel | H1: Payment Method | I1: Product Category | J1: Product Name | K1: Brand | L1: Units Sold | M1: Unit Price | N1: Discount % | O1: Net Sales | P1: Total Price | Q1: Total Units Sold(SUM) | T1: Mobile App | U1: Home & Kitchen | V1: Credit Card | W1: BrandA
A2: 10001 | B2: 1102 | C2: 45197 | D2: 45203 | E2: Chennai | F2: Delhi | G2: Mobile App | H2: Credit Card | I2: Home & Kitchen | J2: Mixer Grinder | K2: BrandA | L2: 7 | M2: 2843.87 | N2: 0 | O2: 19907.09 | P2: =L2*M2 -> 19907.09 | Q2: =SUM(L2:L501) -> 2553 | T2: Website | U2: Sports | V2: Debit Card | W2: BrandD | Y2: AVERAGEA
A3: 10002 | B3: 1435 | C3: 45199 | D3: 45203 | E3: Pune | F3: Tamil Nadu | G3: Website | H3: Debit Card | I3: Sports | J3: Football | K3: BrandD | L3: 9 | M3: 2525.23 | N3: 5 | O3: 21590.72 | P3: =L3*M3 -> 22727.07 | T3: Marketplace | U3: Fashion | V3: Cash on Delivery | W3: BrandE
A4: 10003 | B4: 1860 | C4: 45109 | D4: 45114 | E4: Chennai | F4: West Bengal | G4: Marketplace | H4: Debit Card | I4: Fashion | J4: Sneakers | K4: BrandE | L4: 6 | M4: 3474.34 | N4: 15 | O4: 17719.13 | P4: =L4*M4 -> 20846.04 | U4: Electronics | V4: Net Banking | W4: BrandC | Y4: 5 | Z4: =AVERAGEA(Y4:Y12) -> 2.3333333
A5: 10004 | B5: 1270 | C5: 45079 | D5: 45087 | E5: Bengaluru | F5: West Bengal | G5: Website | H5: Cash on Delivery | I5: Sports | J5: Yoga Mat | K5: BrandA | L5: 1 | M5: 1008.79 | N5: 15 | O5: 857.47 | P5: =L5*M5 -> 1008.79 | U5: Beauty | V5: UPI | W5: BrandB | Y5: 9
A6: 10005 | B6: 1106 | C6: 45241 | D6: 45244 | E6: Kolkata | F6: Karnataka | G6: Marketplace | H6: Credit Card | I6: Fashion | J6: Jacket | K6: BrandA | L6: 7 | M6: 3511.47 | N6: 20 | O6: 19664.23 | P6: =L6*M6 -> 24580.29 | Q6: SUMIF | U6: Books | Y6: 2
A7: 10006 | B7: 1071 | C7: 45260 | D7: 45263 | E7: Hyderabad | F7: Telangana | G7: Website | H7: Net Banking | I7: Home & Kitchen | J7: Bedsheet | K7: BrandE | L7: 3 | M7: 3189.55 | N7: 10 | O7: 8611.78 | P7: =L7*M7 -> 9568.65 | Q7: Product Category | Y7: K
A8: 10007 | B8: 1700 | C8: 45050 | D8: 45054 | E8: Bengaluru | F8: Telangana | G8: Mobile App | H8: UPI | I8: Fashion | J8: Sneakers | K8: BrandC | L8: 5 | M8: 3030.42 | N8: 10 | O8: 13636.89 | P8: =L8*M8 -> 15152.1 | Q8: Sports | R8: =SUMIF(I2:I501,Q8,L2:L501) -> 377 | Y8: G
A9: 10008 | B9: 1020 | C9: 45040 | D9: 45041 | E9: Mumbai | F9: Delhi | G9: Website | H9: Credit Card | I9: Fashion | J9: Sneakers | K9: BrandB | L9: 4 | M9: 2310.83 | N9: 10 | O9: 8318.99 | P9: =L9*M9 -> 9243.32 | Y9: 5
A10: 10009 | B10: 1614 | C10: 45204 | D10: 45213 | E10: Chennai | F10: West Bengal | G10: Website | H10: Debit Card | I10: Fashion | J10: T-Shirt | K10: BrandD | L10: 5 | M10: 1098.04 | N10: 15 | O10: 4666.67 | P10: =L10*M10 -> 5490.2 | Q10: Sales Channel | R10: Net Sales | Y10: @
A11: 10010 | B11: 1121 | C11: 45139 | D11: 45147 | E11: Bengaluru | F11: Karnataka | G11: Website | H11: Cash on Delivery | I11: Electronics | J11: Headphones | K11: BrandB | L11: 5 | M11: 1780.66 | N11: 20 | O11: 7122.64 | P11: =L11*M11 -> 8903.3 | Q11: Mobile App | R11: =SUMIF(G2:G501,Q11,O2:O501) -> 1576040.5 | Y11: 0
A12: 10011 | B12: 1466 | C12: 45098 | D12: 45106 | E12: Bengaluru | F12: Karnataka | G12: Mobile App | H12: Cash on Delivery | I12: Electronics | J12: Headphones | K12: BrandE | L12: 6 | M12: 3205.25 | N12: 0 | O12: 19231.5 | P12: =L12*M12 -> 19231.5 | Y12: *jk
A13: 10012 | B13: 1214 | C13: 45214 | D13: 45220 | E13: Mumbai | F13: Tamil Nadu | G13: Website | H13: UPI | I13: Electronics | J13: Smartwatch | K13: BrandA | L13: 6 | M13: 272.35 | N13: 5 | O13: 1552.39 | P13: =L13*M13 -> 1634.1
A14: 10013 | B14: 1330 | C14: 45100 | D14: 45107 | E14: Delhi | F14: Tamil Nadu | G14: Mobile App | H14: Cash on Delivery | I14: Home & Kitchen | J14: Bedsheet | K14: BrandA | L14: 8 | M14: 3160.9 | N14: 0 | O14: 25287.2 | P14: =L14*M14 -> 25287.2
A15: 10014 | B15: 1458 | C15: 45039 | D15: 45045 | E15: Kolkata | F15: Karnataka | G15: Marketplace | H15: Cash on Delivery | I15: Sports | J15: Yoga Mat | K15: BrandD | L15: 8 | M15: 1074.27 | N15: 15 | O15: 7305.04 | P15: =L15*M15 -> 8594.16 | Q15: SUMIFS
A16: 10015 | B16: 1087 | C16: 45048 | D16: 45057 | E16: Hyderabad | F16: Tamil Nadu | G16: Website | H16: Credit Card | I16: Beauty | J16: Shampoo | K16: BrandA | L16: 9 | M16: 705.59 | N16: 10 | O16: 5715.28 | P16: =L16*M16 -> 6350.31
A17: 10016 | B17: 1372 | C17: 44958 | D17: 44961 | E17: Pune | F17: West Bengal | G17: Mobile App | H17: Net Banking | I17: Fashion | J17: Jacket | K17: BrandA | L17: 8 | M17: 595.45 | N17: 5 | O17: 4525.42 | P17: =L17*M17 -> 4763.6 | Q17: Sales Channel | R17: Product Category | S17: Total Units Sold(SUMIFS)
A18: 10017 | B18: 1099 | C18: 45148 | D18: 45151 | E18: Delhi | F18: Maharashtra | G18: Mobile App | H18: UPI | I18: Fashion | J18: Jacket | K18: BrandD | L18: 2 | M18: 254.91 | N18: 15 | O18: 433.35 | P18: =L18*M18 -> 509.82 | Q18: Website | R18: Electronics | S18: =SUMIFS(L2:L501,G2:G501,Q18,I2:I501,R18) -> 206
A19: 10018 | B19: 1871 | C19: 45045 | D19: 45048 | E19: Chennai | F19: West Bengal | G19: Website | H19: Credit Card | I19: Home & Kitchen | J19: Curtains | K19: BrandD | L19: 1 | M19: 2165.81 | N19: 15 | O19: 1840.94 | P19: =L19*M19 -> 2165.81
A20: 10019 | B20: 1663 | C20: 44965 | D20: 44968 | E20: Bengaluru | F20: Karnataka | G20: Marketplace | H20: Net Banking | I20: Fashion | J20: Jacket | K20: BrandE | L20: 2 | M20: 990.3 | N20: 15 | O20: 1683.51 | P20: =L20*M20 -> 1980.6 | Q20: Payment Method | R20: Brand | S20: Net Sales
A21: 10020 | B21: 1130 | C21: 45194 | D21: 45203 | E21: Mumbai | F21: Karnataka | G21: Mobile App | H21: Credit Card | I21: Electronics | J21: Smartwatch | K21: BrandA | L21: 2 | M21: 3959.31 | N21: 5 | O21: 7522.69 | P21: =L21*M21 -> 7918.62 | Q21: Net Banking | R21: BrandE | S21: =SUMIFS(O2:O501,H2:H501,Q21,K2:K501,R21) -> 163401.52
A22: 10021 | B22: 1661 | C22: 45159 | D22: 45163 | E22: Mumbai | F22: West Bengal | G22: Website | H22: Credit Card | I22: Beauty | J22: Lipstick | K22: BrandA | L22: 3 | M22: 2361.58 | N22: 5 | O22: 6730.5 | P22: =L22*M22 -> 7084.74
A23: 10022 | B23: 1308 | C23: 44944 | D23: 44951 | E23: Kolkata | F23: Tamil Nadu | G23: Marketplace | H23: Cash on Delivery | I23: Books | J23: Fiction Novel | K23: BrandE | L23: 7 | M23: 680.86 | N23: 20 | O23: 3812.82 | P23: =L23*M23 -> 4766.02 | Q23: Grand Total | R23: =SUM(P2:P501) -> 5134263.8
A24: 10023 | B24: 1769 | C24: 45075 | D24: 45084 | E24: Delhi | F24: Tamil Nadu | G24: Mobile App | H24: Net Banking | I24: Fashion | J24: Sneakers | K24: BrandC | L24: 2 | M24: 2801.74 | N24: 20 | O24: 4482.78 | P24: =L24*M24 -> 5603.48
A25: 10024 | B25: 1343 | C25: 45075 | D25: 45082 | E25: Pune | F25: Telangana | G25: Mobile App | H25: UPI | I25: Electronics | J25: Smartwatch | K25: BrandC | L25: 1 | M25: 3606.31 | N25: 0 | O25: 3606.31 | P25: =L25*M25 -> 3606.31 | Q25: Using ARRAY
A26: 10025 | B26: 1491 | C26: 45052 | D26: 45061 | E26: Kolkata | F26: Karnataka | G26: Marketplace | H26: UPI | I26: Books | J26: Comics | K26: BrandC | L26: 6 | M26: 3018.94 | N26: 5 | O26: 17207.96 | P26: =L26*M26 -> 18113.64 | Q26: Grand Total | R26: =SUMPRODUCT(L2:L501,M2:M501) -> 5134263.8
A27: 10026 | B27: 1413 | C27: 45228 | D27: 45231 | E27: Bengaluru | F27: Delhi | G27: Marketplace | H27: Net Banking | I27: Beauty | J27: Perfume | K27: BrandE | L27: 9 | M27: 444.29 | N27: 5 | O27: 3798.68 | P27: =L27*M27 -> 3998.61 | Q27: Total Discount Amount | R27: =SUMPRODUCT(L2:L501,M2:M501,N2:N501)/100 -> 519774.77
A28: 10027 | B28: 1805 | C28: 45286 | D28: 45290 | E28: Kolkata | F28: Telangana | G28: Website | H28: Cash on Delivery | I28: Books | J28: Fiction Novel | K28: BrandA | L28: 3 | M28: 3599.15 | N28: 5 | O28: 10257.58 | P28: =L28*M28 -> 10797.45 | Q28: Using AVERAGEIF
A29: 10028 | B29: 1385 | C29: 45164 | D29: 45172 | E29: Hyderabad | F29: Tamil Nadu | G29: Website | H29: Debit Card | I29: Electronics | J29: Smartwatch | K29: BrandE | L29: 6 | M29: 3206.63 | N29: 20 | O29: 15391.82 | P29: =L29*M29 -> 19239.78 | Q29: Brand | R29: Avg. Net Sales
A30: 10029 | B30: 1191 | C30: 45061 | D30: 45067 | E30: Mumbai | F30: West Bengal | G30: Mobile App | H30: Credit Card | I30: Sports | J30: Football | K30: BrandE | L30: 3 | M30: 759.47 | N30: 15 | O30: 1936.65 | P30: =L30*M30 -> 2278.41 | Q30: BrandB | R30: =AVERAGEIF(K2:K501,Q30,O2:O501) -> 9778.0083
A31: 10030 | B31: 1955 | C31: 45077 | D31: 45082 | E31: Mumbai | F31: Tamil Nadu | G31: Marketplace | H31: Cash on Delivery | I31: Sports | J31: Cricket Bat | K31: BrandC | L31: 1 | M31: 349.38 | N31: 10 | O31: 314.44 | P31: =L31*M31 -> 349.38
A32: 10031 | B32: 1276 | C32: 45162 | D32: 45166 | E32: Chennai | F32: West Bengal | G32: Marketplace | H32: Net Banking | I32: Books | J32: Textbook | K32: BrandB | L32: 5 | M32: 2295.65 | N32: 20 | O32: 9182.6 | P32: =L32*M32 -> 11478.25 | Q32: Using AVERAGEIFS
A33: 10032 | B33: 1160 | C33: 45150 | D33: 45158 | E33: Chennai | F33: Telangana | G33: Marketplace | H33: Credit Card | I33: Home & Kitchen | J33: Bedsheet | K33: BrandA | L33: 4 | M33: 750.74 | N33: 5 | O33: 2852.81 | P33: =L33*M33 -> 3002.96 | Q33: Brand | R33: Sales Channel | S33: Avg. Net Sales
A34: 10033 | B34: 1459 | C34: 45129 | D34: 45130 | E34: Pune | F34: Karnataka | G34: Mobile App | H34: UPI | I34: Books | J34: Comics | K34: BrandC | L34: 7 | M34: 3363.18 | N34: 20 | O34: 18833.81 | P34: =L34*M34 -> 23542.26 | Q34: BrandC | R34: Website | S34: =AVERAGEIFS(O2:O501,K2:K501,Q34,G2:G501,R34) -> 7414.8813
A35: 10034 | B35: 1313 | C35: 45182 | D35: 45191 | E35: Bengaluru | F35: Tamil Nadu | G35: Marketplace | H35: Debit Card | I35: Fashion | J35: T-Shirt | K35: BrandB | L35: 6 | M35: 1529.59 | N35: 0 | O35: 9177.54 | P35: =L35*M35 -> 9177.54
A36: 10035 | B36: 1021 | C36: 45012 | D36: 45013 | E36: Hyderabad | F36: West Bengal | G36: Marketplace | H36: UPI | I36: Fashion | J36: T-Shirt | K36: BrandB | L36: 7 | M36: 3664.64 | N36: 5 | O36: 24369.86 | P36: =L36*M36 -> 25652.48
A37: 10036 | B37: 1252 | C37: 45076 | D37: 45084 | E37: Delhi | F37: Karnataka | G37: Mobile App | H37: Net Banking | I37: Sports | J37: Football | K37: BrandD | L37: 5 | M37: 2327.9 | N37: 0 | O37: 11639.5 | P37: =L37*M37 -> 11639.5
A38: 10037 | B38: 1747 | C38: 45161 | D38: 45165 | E38: Kolkata | F38: Delhi | G38: Website | H38: Credit Card | I38: Home & Kitchen | J38: Curtains | K38: BrandA | L38: 4 | M38: 853.29 | N38: 5 | O38: 3242.5 | P38: =L38*M38 -> 3413.16
A39: 10038 | B39: 1856 | C39: 45271 | D39: 45280 | E39: Pune | F39: West Bengal | G39: Website | H39: Net Banking | I39: Electronics | J39: Laptop | K39: BrandB | L39: 7 | M39: 687.46 | N39: 20 | O39: 3849.78 | P39: =L39*M39 -> 4812.22
A40: 10039 | B40: 1560 | C40: 44948 | D40: 44953 | E40: Bengaluru | F40: Telangana | G40: Mobile App | H40: Credit Card | I40: Fashion | J40: T-Shirt | K40: BrandC | L40: 7 | M40: 2369.42 | N40: 15 | O40: 14098.05 | P40: =L40*M40 -> 16585.94
...

Sheet Day3 30.09.2026
A1: Order ID | B1: Customer ID | C1: Order Date | D1: Ship Date | E1: City | F1: State | G1: Sales Channel | H1: Payment Method | I1: Product Category | J1: Product Name | K1: Brand | L1: Units Sold | M1: Unit Price | N1: Discount % | O1: Net Sales | P1: Total Price | R1: High Value Order | S1: Bulk Order | U1: Priority Channel | W1: Sales Status | Y1: Website Order | AA1: Website Order | AD1: Category | AF1: Order Type
A2: 10001 | B2: 1102 | C2: 45197 | D2: 45203 | E2: Chennai | F2: Delhi | G2: Mobile App | H2: Credit Card | I2: Home & Kitchen | J2: Mixer Grinder | K2: BrandA | L2: 7 | M2: 2843.87 | N2: 0 | O2: 19907.09 | P2: =L2*M2 -> 19907.09 | R2: =IF(AND(L2>5,O2>10000),"YES","NO") -> YES | S2: =IF(AND(L2>=8,N2>=10),"YES","NO") -> NO | U2: =IF(OR(G2="Mobile App",G2="Website"),"YES","NO") -> YES | W2: =IF(AND(L2<3,O2<=1000),"Special Attention","No") -> No | Y2: =IF(NOT(G2="Website"),"No","yes") -> No | AA2: =IF(G2<>"Website","No","Yes") -> No | AD2: =IF(AND(O2>15000,OR(I2="Electronics",I2="Beauty")),"Premium","Regular") -> Regular | AF2: =IF(AND(L2>=8,N2<>0),"Non Disc","Discounted") -> Discounted
A3: 10002 | B3: 1435 | C3: 45199 | D3: 45203 | E3: Pune | F3: Tamil Nadu | G3: Website | H3: Debit Card | I3: Sports | J3: Football | K3: BrandD | L3: 9 | M3: 2525.23 | N3: 5 | O3: 21590.72 | P3: =L3*M3 -> 22727.07 | R3: =IF(AND(L3>5,O3>10000),"YES","NO") -> YES | S3: =IF(AND(L3>=8,N3>=10),"YES","NO") -> NO | U3: =IF(OR(G3="Mobile App",G3="Website"),"YES","NO") -> YES | W3: =IF(AND(L3<3,O3<=1000),"Special Attention","No") -> No | Y3: =IF(NOT(G3="Website"),"No","yes") -> yes | AA3: =IF(G3<>"Website","No","Yes") -> Yes | AD3: =IF(AND(O3>15000,OR(I3="Electronics",I3="Beauty")),"Premium","Regular") -> Regular | AF3: =IF(AND(L3>=8,N3<>0),"Non Disc","Discounted") -> Non Disc
A4: 10003 | B4: 1860 | C4: 45109 | D4: 45114 | E4: Chennai | F4: West Bengal | G4: Marketplace | H4: Debit Card | I4: Fashion | J4: Sneakers | K4: BrandE | L4: 6 | M4: 3474.34 | N4: 15 | O4: 17719.13 | P4: =L4*M4 -> 20846.04 | R4: =IF(AND(L4>5,O4>10000),"YES","NO") -> YES | S4: =IF(AND(L4>=8,N4>=10),"YES","NO") -> NO | U4: =IF(OR(G4="Mobile App",G4="Website"),"YES","NO") -> NO | W4: =IF(AND(L4<3,O4<=1000),"Special Attention","No") -> No | Y4: =IF(NOT(G4="Website"),"No","yes") -> No | AA4: =IF(G4<>"Website","No","Yes") -> No | AD4: =IF(AND(O4>15000,OR(I4="Electronics",I4="Beauty")),"Premium","Regular") -> Regular | AF4: =IF(AND(L4>=8,N4<>0),"Non Disc","Discounted") -> Discounted
A5: 10004 | B5: 1270 | C5: 45079 | D5: 45087 | E5: Bengaluru | F5: West Bengal | G5: Website | H5: Cash on Delivery | I5: Sports | J5: Yoga Mat | K5: BrandA | L5: 1 | M5: 1008.79 | N5: 15 | O5: 857.47 | P5: =L5*M5 -> 1008.79 | R5: =IF(AND(L5>5,O5>10000),"YES","NO") -> NO | S5: =IF(AND(L5>=8,N5>=10),"YES","NO") -> NO | U5: =IF(OR(G5="Mobile App",G5="Website"),"YES","NO") -> YES | W5: =IF(AND(L5<3,O5<=1000),"Special Attention","No") -> Special Attention | Y5: =IF(NOT(G5="Website"),"No","yes") -> yes | AA5: =IF(G5<>"Website","No","Yes") -> Yes | AD5: =IF(AND(O5>15000,OR(I5="Electronics",I5="Beauty")),"Premium","Regular") -> Regular | AF5: =IF(AND(L5>=8,N5<>0),"Non Disc","Discounted") -> Discounted
A6: 10005 | B6: 1106 | C6: 45241 | D6: 45244 | E6: Kolkata | F6: Karnataka | G6: Marketplace | H6: Credit Card | I6: Fashion | J6: Jacket | K6: BrandA | L6: 7 | M6: 3511.47 | N6: 20 | O6: 19664.23 | P6: =L6*M6 -> 24580.29 | Q6: Uses of "AND" | R6: =IF(AND(L6>5,O6>10000),"YES","NO") -> YES | S6: =IF(AND(L6>=8,N6>=10),"YES","NO") -> NO | T6: Uses of "OR" | U6: =IF(OR(G6="Mobile App",G6="Website"),"YES","NO") -> NO | V6: Uses of "AND" | W6: =IF(AND(L6<3,O6<=1000),"Special Attention","No") -> No | X6: Uses of "NOT" | Y6: =IF(NOT(G6="Website"),"No","yes") -> No | Z6: Uses of "<>" | AA6: =IF(G6<>"Website","No","Yes") -> No | AB6: Uses of "AND","OR" | AD6: =IF(AND(O6>15000,OR(I6="Electronics",I6="Beauty")),"Premium","Regular") -> Regular | AE6: Uses of "AND","OR" | AF6: =IF(AND(L6>=8,N6<>0),"Non Disc","Discounted") -> Discounted
A7: 10006 | B7: 1071 | C7: 45260 | D7: 45263 | E7: Hyderabad | F7: Telangana | G7: Website | H7: Net Banking | I7: Home & Kitchen | J7: Bedsheet | K7: BrandE | L7: 3 | M7: 3189.55 | N7: 10 | O7: 8611.78 | P7: =L7*M7 -> 9568.65 | R7: =IF(AND(L7>5,O7>10000),"YES","NO") -> NO | S7: =IF(AND(L7>=8,N7>=10),"YES","NO") -> NO | U7: =IF(OR(G7="Mobile App",G7="Website"),"YES","NO") -> YES | W7: =IF(AND(L7<3,O7<=1000),"Special Attention","No") -> No | Y7: =IF(NOT(G7="Website"),"No","yes") -> yes | AA7: =IF(G7<>"Website","No","Yes") -> Yes | AD7: =IF(AND(O7>15000,OR(I7="Electronics",I7="Beauty")),"Premium","Regular") -> Regular | AF7: =IF(AND(L7>=8,N7<>0),"Non Disc","Discounted") -> Discounted
A8: 10007 | B8: 1700 | C8: 45050 | D8: 45054 | E8: Bengaluru | F8: Telangana | G8: Mobile App | H8: UPI | I8: Fashion | J8: Sneakers | K8: BrandC | L8: 5 | M8: 3030.42 | N8: 10 | O8: 13636.89 | P8: =L8*M8 -> 15152.1 | R8: =IF(AND(L8>5,O8>10000),"YES","NO") -> NO | S8: =IF(AND(L8>=8,N8>=10),"YES","NO") -> NO | U8: =IF(OR(G8="Mobile App",G8="Website"),"YES","NO") -> YES | W8: =IF(AND(L8<3,O8<=1000),"Special Attention","No") -> No | Y8: =IF(NOT(G8="Website"),"No","yes") -> No | AA8: =IF(G8<>"Website","No","Yes") -> No | AD8: =IF(AND(O8>15000,OR(I8="Electronics",I8="Beauty")),"Premium","Regular") -> Regular | AF8: =IF(AND(L8>=8,N8<>0),"Non Disc","Discounted") -> Discounted
A9: 10008 | B9: 1020 | C9: 45040 | D9: 45041 | E9: Mumbai | F9: Delhi | G9: Website | H9: Credit Card | I9: Fashion | J9: Sneakers | K9: BrandB | L9: 4 | M9: 2310.83 | N9: 10 | O9: 8318.99 | P9: =L9*M9 -> 9243.32 | R9: =IF(AND(L9>5,O9>10000),"YES","NO") -> NO | S9: =IF(AND(L9>=8,N9>=10),"YES","NO") -> NO | U9: =IF(OR(G9="Mobile App",G9="Website"),"YES","NO") -> YES | W9: =IF(AND(L9<3,O9<=1000),"Special Attention","No") -> No | Y9: =IF(NOT(G9="Website"),"No","yes") -> yes | AA9: =IF(G9<>"Website","No","Yes") -> Yes | AD9: =IF(AND(O9>15000,OR(I9="Electronics",I9="Beauty")),"Premium","Regular") -> Regular | AF9: =IF(AND(L9>=8,N9<>0),"Non Disc","Discounted") -> Discounted
A10: 10009 | B10: 1614 | C10: 45204 | D10: 45213 | E10: Chennai | F10: West Bengal | G10: Website | H10: Debit Card | I10: Fashion | J10: T-Shirt | K10: BrandD | L10: 5 | M10: 1098.04 | N10: 15 | O10: 4666.67 | P10: =L10*M10 -> 5490.2 | R10: =IF(AND(L10>5,O10>10000),"YES","NO") -> NO | S10: =IF(AND(L10>=8,N10>=10),"YES","NO") -> NO | U10: =IF(OR(G10="Mobile App",G10="Website"),"YES","NO") -> YES | W10: =IF(AND(L10<3,O10<=1000),"Special Attention","No") -> No | Y10: =IF(NOT(G10="Website"),"No","yes") -> yes | AA10: =IF(G10<>"Website","No","Yes") -> Yes | AD10: =IF(AND(O10>15000,OR(I10="Electronics",I10="Beauty")),"Premium","Regular") -> Regular | AF10: =IF(AND(L10>=8,N10<>0),"Non Disc","Discounted") -> Discounted
A11: 10010 | B11: 1121 | C11: 45139 | D11: 45147 | E11: Bengaluru | F11: Karnataka | G11: Website | H11: Cash on Delivery | I11: Electronics | J11: Headphones | K11: BrandB | L11: 5 | M11: 1780.66 | N11: 20 | O11: 7122.64 | P11: =L11*M11 -> 8903.3 | R11: =IF(AND(L11>5,O11>10000),"YES","NO") -> NO | S11: =IF(AND(L11>=8,N11>=10),"YES","NO") -> NO | U11: =IF(OR(G11="Mobile App",G11="Website"),"YES","NO") -> YES | W11: =IF(AND(L11<3,O11<=1000),"Special Attention","No") -> No | Y11: =IF(NOT(G11="Website"),"No","yes") -> yes | AA11: =IF(G11<>"Website","No","Yes") -> Yes | AD11: =IF(AND(O11>15000,OR(I11="Electronics",I11="Beauty")),"Premium","Regular") -> Regular | AF11: =IF(AND(L11>=8,N11<>0),"Non Disc","Discounted") -> Discounted
A12: 10011 | B12: 1466 | C12: 45098 | D12: 45106 | E12: Bengaluru | F12: Karnataka | G12: Mobile App | H12: Cash on Delivery | I12: Electronics | J12: Headphones | K12: BrandE | L12: 6 | M12: 3205.25 | N12: 0 | O12: 19231.5 | P12: =L12*M12 -> 19231.5 | R12: =IF(AND(L12>5,O12>10000),"YES","NO") -> YES | S12: =IF(AND(L12>=8,N12>=10),"YES","NO") -> NO | U12: =IF(OR(G12="Mobile App",G12="Website"),"YES","NO") -> YES | W12: =IF(AND(L12<3,O12<=1000),"Special Attention","No") -> No | Y12: =IF(NOT(G12="Website"),"No","yes") -> No | AA12: =IF(G12<>"Website","No","Yes") -> No | AD12: =IF(AND(O12>15000,OR(I12="Electronics",I12="Beauty")),"Premium","Regular") -> Premium | AF12: =IF(AND(L12>=8,N12<>0),"Non Disc","Discounted") -> Discounted
A13: 10012 | B13: 1214 | C13: 45214 | D13: 45220 | E13: Mumbai | F13: Tamil Nadu | G13: Website | H13: UPI | I13: Electronics | J13: Smartwatch | K13: BrandA | L13: 6 | M13: 272.35 | N13: 5 | O13: 1552.39 | P13: =L13*M13 -> 1634.1 | R13: =IF(AND(L13>5,O13>10000),"YES","NO") -> NO | S13: =IF(AND(L13>=8,N13>=10),"YES","NO") -> NO | U13: =IF(OR(G13="Mobile App",G13="Website"),"YES","NO") -> YES | W13: =IF(AND(L13<3,O13<=1000),"Special Attention","No") -> No | Y13: =IF(NOT(G13="Website"),"No","yes") -> yes | AA13: =IF(G13<>"Website","No","Yes") -> Yes | AD13: =IF(AND(O13>15000,OR(I13="Electronics",I13="Beauty")),"Premium","Regular") -> Regular | AF13: =IF(AND(L13>=8,N13<>0),"Non Disc","Discounted") -> Discounted
A14: 10013 | B14: 1330 | C14: 45100 | D14: 45107 | E14: Delhi | F14: Tamil Nadu | G14: Mobile App | H14: Cash on Delivery | I14: Home & Kitchen | J14: Bedsheet | K14: BrandA | L14: 8 | M14: 3160.9 | N14: 0 | O14: 25287.2 | P14: =L14*M14 -> 25287.2 | R14: =IF(AND(L14>5,O14>10000),"YES","NO") -> YES | S14: =IF(AND(L14>=8,N14>=10),"YES","NO") -> NO | U14: =IF(OR(G14="Mobile App",G14="Website"),"YES","NO") -> YES | W14: =IF(AND(L14<3,O14<=1000),"Special Attention","No") -> No | Y14: =IF(NOT(G14="Website"),"No","yes") -> No | AA14: =IF(G14<>"Website","No","Yes") -> No | AD14: =IF(AND(O14>15000,OR(I14="Electronics",I14="Beauty")),"Premium","Regular") -> Regular | AF14: =IF(AND(L14>=8,N14<>0),"Non Disc","Discounted") -> Discounted
A15: 10014 | B15: 1458 | C15: 45039 | D15: 45045 | E15: Kolkata | F15: Karnataka | G15: Marketplace | H15: Cash on Delivery | I15: Sports | J15: Yoga Mat | K15: BrandD | L15: 8 | M15: 1074.27 | N15: 15 | O15: 7305.04 | P15: =L15*M15 -> 8594.16 | R15: =IF(AND(L15>5,O15>10000),"YES","NO") -> NO | S15: =IF(AND(L15>=8,N15>=10),"YES","NO") -> YES | U15: =IF(OR(G15="Mobile App",G15="Website"),"YES","NO") -> NO | W15: =IF(AND(L15<3,O15<=1000),"Special Attention","No") -> No | Y15: =IF(NOT(G15="Website"),"No","yes") -> No | AA15: =IF(G15<>"Website","No","Yes") -> No | AD15: =IF(AND(O15>15000,OR(I15="Electronics",I15="Beauty")),"Premium","Regular") -> Regular | AF15: =IF(AND(L15>=8,N15<>0),"Non Disc","Discounted") -> Non Disc
A16: 10015 | B16: 1087 | C16: 45048 | D16: 45057 | E16: Hyderabad | F16: Tamil Nadu | G16: Website | H16: Credit Card | I16: Beauty | J16: Shampoo | K16: BrandA | L16: 9 | M16: 705.59 | N16: 10 | O16: 5715.28 | P16: =L16*M16 -> 6350.31 | R16: =IF(AND(L16>5,O16>10000),"YES","NO") -> NO | S16: =IF(AND(L16>=8,N16>=10),"YES","NO") -> YES | U16: =IF(OR(G16="Mobile App",G16="Website"),"YES","NO") -> YES | W16: =IF(AND(L16<3,O16<=1000),"Special Attention","No") -> No | Y16: =IF(NOT(G16="Website"),"No","yes") -> yes | AA16: =IF(G16<>"Website","No","Yes") -> Yes | AD16: =IF(AND(O16>15000,OR(I16="Electronics",I16="Beauty")),"Premium","Regular") -> Regular | AF16: =IF(AND(L16>=8,N16<>0),"Non Disc","Discounted") -> Non Disc
A17: 10016 | B17: 1372 | C17: 44958 | D17: 44961 | E17: Pune | F17: West Bengal | G17: Mobile App | H17: Net Banking | I17: Fashion | J17: Jacket | K17: BrandA | L17: 8 | M17: 595.45 | N17: 5 | O17: 4525.42 | P17: =L17*M17 -> 4763.6 | R17: =IF(AND(L17>5,O17>10000),"YES","NO") -> NO | S17: =IF(AND(L17>=8,N17>=10),"YES","NO") -> NO | U17: =IF(OR(G17="Mobile App",G17="Website"),"YES","NO") -> YES | W17: =IF(AND(L17<3,O17<=1000),"Special Attention","No") -> No | Y17: =IF(NOT(G17="Website"),"No","yes") -> No | AA17: =IF(G17<>"Website","No","Yes") -> No | AD17: =IF(AND(O17>15000,OR(I17="Electronics",I17="Beauty")),"Premium","Regular") -> Regular | AF17: =IF(AND(L17>=8,N17<>0),"Non Disc","Discounted") -> Non Disc
A18: 10017 | B18: 1099 | C18: 45148 | D18: 45151 | E18: Delhi | F18: Maharashtra | G18: Mobile App | H18: UPI | I18: Fashion | J18: Jacket | K18: BrandD | L18: 2 | M18: 254.91 | N18: 15 | O18: 433.35 | P18: =L18*M18 -> 509.82 | R18: =IF(AND(L18>5,O18>10000),"YES","NO") -> NO | S18: =IF(AND(L18>=8,N18>=10),"YES","NO") -> NO | U18: =IF(OR(G18="Mobile App",G18="Website"),"YES","NO") -> YES | W18: =IF(AND(L18<3,O18<=1000),"Special Attention","No") -> Special Attention | Y18: =IF(NOT(G18="Website"),"No","yes") -> No | AA18: =IF(G18<>"Website","No","Yes") -> No | AD18: =IF(AND(O18>15000,OR(I18="Electronics",I18="Beauty")),"Premium","Regular") -> Regular | AF18: =IF(AND(L18>=8,N18<>0),"Non Disc","Discounted") -> Discounted
... A501: 10500 | B501: 1569 | C501: 44972 | D501: 44977 | E501: Chennai | F501: Delhi | G501: Marketplace | H501: Net Banking | I501: Fashion | J501: Jeans | K501: BrandE | L501: 1 | M501: 2432.17 | N501: 20 | O501: 1945.74 | P501: =L501*M501 -> 2432.17 | R501: =IF(AND(L501>5,O501>10000),"YES","NO") -> NO | S501: =IF(AND(L501>=8,N501>=10),"YES","NO") -> NO | U501: =IF(OR(G501="Mobile App",G501="Website"),"YES","NO") -> NO | W501: =IF(AND(L501<3,O501<=1000),"Special Attention","No") -> No | Y501: =IF(NOT(G501="Website"),"No","yes") -> No | AA501: =IF(G501<>"Website","No","Yes") -> No | AD501: =IF(AND(O501>15000,OR(I501="Electronics",I501="Beauty")),"Premium","Regular") -> Regular | AF501: =IF(AND(L501>=8,N501<>0),"Non Disc","Discounted") -> Discounted

Sheet Day4 01.10.2026 s&f
A1: Order ID | B1: Customer ID | C1: Order Date | D1: Ship Date | E1: City | F1: State | G1: Sales Channel | H1: Payment Method | I1: Product Category | J1: Product Name | K1: Brand | L1: Units Sold | M1: Unit Price | N1: Discount % | O1: Net Sales | R1: City
A2: 10045 | B2: 1699 | C2: 45139 | D2: 45147 | E2: Bengaluru | F2: Delhi | G2: Mobile App | H2: Debit Card | I2: Sports | J2: Cricket Bat | K2: BrandB | L2: 1 | M2: 2764.92 | N2: 0 | O2: 2764.92 | R2: Bengaluru | U2: Order ID | V2: Customer ID | W2: Order Date | X2: Ship Date | Y2: City | Z2: State | AA2: Sales Channel | AB2: Payment Method | AC2: Product Category | AD2: Product Name | AE2: Brand | AF2: Units Sold | AG2: Unit Price | AH2: Discount % | AI2: Net Sales
A3: 10295 | B3: 1637 | C3: 45280 | D3: 45284 | E3: Bengaluru | F3: Tamil Nadu | G3: Website | H3: Net Banking | I3: Fashion | J3: T-Shirt | K3: BrandE | L3: 1 | M3: 619.73 | N3: 0 | O3: 619.73 | U3: 10045 | V3: 1699 | W3: 45139 | X3: 45147 | Y3: Bengaluru | Z3: Delhi | AA3: Mobile App | AB3: Debit Card | AC3: Sports | AD3: Cricket Bat | AE3: BrandB | AF3: 1 | AG3: 2764.92 | AH3: 0 | AI3: 2764.92
A4: 10004 | B4: 1270 | C4: 45079 | D4: 45087 | E4: Bengaluru | F4: West Bengal | G4: Website | H4: Cash on Delivery | I4: Sports | J4: Yoga Mat | K4: BrandA | L4: 1 | M4: 1008.79 | N4: 15 | O4: 857.47 | U4: 10295 | V4: 1637 | W4: 45280 | X4: 45284 | Y4: Bengaluru | Z4: Tamil Nadu | AA4: Website | AB4: Net Banking | AC4: Fashion | AD4: T-Shirt | AE4: BrandE | AF4: 1 | AG4: 619.73 | AH4: 0 | AI4: 619.73
A5: 10309 | B5: 1400 | C5: 44928 | D5: 44936 | E5: Bengaluru | F5: West Bengal | G5: Marketplace | H5: UPI | I5: Electronics | J5: Smartwatch | K5: BrandB | L5: 1 | M5: 2740.46 | N5: 10 | O5: 2466.41 | U5: 10004 | V5: 1270 | W5: 45079 | X5: 45087 | Y5: Bengaluru | Z5: West Bengal | AA5: Website | AB5: Cash on Delivery | AC5: Sports | AD5: Yoga Mat | AE5: BrandA | AF5: 1 | AG5: 1008.79 | AH5: 15 | AI5: 857.47
A6: 10345 | B6: 1935 | C6: 44984 | D6: 44993 | E6: Bengaluru | F6: West Bengal | G6: Marketplace | H6: Net Banking | I6: Sports | J6: Yoga Mat | K6: BrandC | L6: 1 | M6: 3625.42 | N6: 10 | O6: 3262.88 | U6: 10309 | V6: 1400 | W6: 44928 | X6: 44936 | Y6: Bengaluru | Z6: West Bengal | AA6: Marketplace | AB6: UPI | AC6: Electronics | AD6: Smartwatch | AE6: BrandB | AF6: 1 | AG6: 2740.46 | AH6: 10 | AI6: 2466.41
A7: 10019 | B7: 1663 | C7: 44965 | D7: 44968 | E7: Bengaluru | F7: Karnataka | G7: Marketplace | H7: Net Banking | I7: Fashion | J7: Jacket | K7: BrandE | L7: 2 | M7: 990.3 | N7: 15 | O7: 1683.51 | U7: 10345 | V7: 1935 | W7: 44984 | X7: 44993 | Y7: Bengaluru | Z7: West Bengal | AA7: Marketplace | AB7: Net Banking | AC7: Sports | AD7: Yoga Mat | AE7: BrandC | AF7: 1 | AG7: 3625.42 | AH7: 10 | AI7: 3262.88
A8: 10317 | B8: 1981 | C8: 45051 | D8: 45056 | E8: Bengaluru | F8: Karnataka | G8: Website | H8: Debit Card | I8: Electronics | J8: Laptop | K8: BrandB | L8: 2 | M8: 788.72 | N8: 20 | O8: 1261.95 | U8: 10019 | V8: 1663 | W8: 44965 | X8: 44968 | Y8: Bengaluru | Z8: Karnataka | AA8: Marketplace | AB8: Net Banking | AC8: Fashion | AD8: Jacket | AE8: BrandE | AF8: 2 | AG8: 990.3 | AH8: 15 | AI8: 1683.51
A9: 10331 | B9: 1763 | C9: 45203 | D9: 45207 | E9: Bengaluru | F9: Karnataka | G9: Mobile App | H9: Cash on Delivery | I9: Home & Kitchen | J9: Curtains | K9: BrandB | L9: 2 | M9: 2481.1 | N9: 15 | O9: 4217.87 | U9: 10317 | V9: 1981 | W9: 45051 | X9: 45056 | Y9: Bengaluru | Z9: Karnataka | AA9: Website | AB9: Debit Card | AC9: Electronics | AD9: Laptop | AE9: BrandB | AF9: 2 | AG9: 788.72 | AH9: 20 | AI9: 1261.95
A10: 10190 | B10: 1857 | C10: 45185 | D10: 45187 | E10: Bengaluru | F10: Maharashtra | G10: Marketplace | H10: Debit Card | I10: Electronics | J10: Smartwatch | K10: BrandA | L10: 2 | M10: 1372.59 | N10: 5 | O10: 2607.92 | U10: 10331 | V10: 1763 | W10: 45203 | X10: 45207 | Y10: Bengaluru | Z10: Karnataka | AA10: Mobile App | AB10: Cash on Delivery | AC10: Home & Kitchen | AD10: Curtains | AE10: BrandB | AF10: 2 | AG10: 2481.1 | AH10: 15 | AI10: 4217.87
A11: 10477 | B11: 1279 | C11: 45229 | D11: 45230 | E11: Bengaluru | F11: Maharashtra | G11: Marketplace | H11: UPI | I11: Fashion | J11: T-Shirt | K11: BrandC | L11: 2 | M11: 2962.4 | N11: 0 | O11: 5924.8 | U11: 10190 | V11: 1857 | W11: 45185 | X11: 45187 | Y11: Bengaluru | Z11: Maharashtra | AA11: Marketplace | AB11: Debit Card | AC11: Electronics | AD11: Smartwatch | AE11: BrandA | AF11: 2 | AG11: 1372.59 | AH11: 5 | AI11: 2607.92
A12: 10224 | B12: 1795 | C12: 45100 | D12: 45106 | E12: Bengaluru | F12: Tamil Nadu | G12: Marketplace | H12: Debit Card | I12: Books | J12: Fiction Novel | K12: BrandA | L12: 2 | M12: 1448.65 | N12: 20 | O12: 2317.84 | U12: 10477 | V12: 1279 | W12: 45229 | X12: 45230 | Y12: Bengaluru | Z12: Maharashtra | AA12: Marketplace | AB12: UPI | AC12: Fashion | AD12: T-Shirt | AE12: BrandC | AF12: 2 | AG12: 2962.4 | AH12: 0 | AI12: 5924.8
A13: 10194 | B13: 1690 | C13: 45180 | D13: 45182 | E13: Bengaluru | F13: Telangana | G13: Website | H13: Debit Card | I13: Books | J13: Comics | K13: BrandC | L13: 2 | M13: 894.01 | N13: 15 | O13: 1519.82 | U13: 10224 | V13: 1795 | W13: 45100 | X13: 45106 | Y13: Bengaluru | Z13: Tamil Nadu | AA13: Marketplace | AB13: Debit Card | AC13: Books | AD13: Fiction Novel | AE13: BrandA | AF13: 2 | AG13: 1448.65 | AH13: 20 | AI13: 2317.84
A14: 10239 | B14: 1384 | C14: 45146 | D14: 45149 | E14: Bengaluru | F14: Telangana | G14: Website | H14: Debit Card | I14: Electronics | J14: Laptop | K14: BrandB | L14: 2 | M14: 3960.56 | N14: 10 | O14: 7129.01 | U14: 10194 | V14: 1690 | W14: 45180 | X14: 45182 | Y14: Bengaluru | Z14: Telangana | AA14: Website | AB14: Debit Card | AC14: Books | AD14: Comics | AE14: BrandC | AF14: 2 | AG14: 894.01 | AH14: 15 | AI14: 1519.82
... A60: 10379 | B60: 1658 | C60: 45262 | D60: 45270 | E60: Chennai | F60: Delhi | G60: Website | H60: Cash on Delivery | I60: Sports | J60: Dumbbells | K60: BrandC | L60: 1 | M60: 3910.66 | N60: 5 | O60: 3715.13 | U60: 10353 | V60: 1952 | W60: 44968 | X60: 44972 | Y60: Bengaluru | Z60: West Bengal | AA60: Marketplace | AB60: UPI | AC60: Books | AD60: Biography | AE60: BrandE | AF60: 9 | AG60: 1375.31 | AH60: 15 | AI60: 10521.12
A61: 10500 | B61: 1569 | C61: 44972 | D61: 44977 | E61: Chennai | F61: Delhi | G61: Marketplace | H61: Net Banking | I61: Fashion | J61: Jeans | K61: BrandE | L61: 1 | M61: 2432.17 | N61: 20 | O61: 1945.74
A62: 10111 | B62: 1461 | C62: 44950 | D62: 44959 | E62: Chennai | F62: Maharashtra | G62: Marketplace | H62: Cash on Delivery | I62: Electronics | J62: Smartphone | K62: BrandE | L62: 1 | M62: 1820.02 | N62: 10 | O62: 1638.02
A63: 10130 | B63: 1156 | C63: 44929 | D63: 44938 | E63: Chennai | F63: Telangana | G63: Mobile App | H63: Net Banking | I63: Books | J63: Textbook | K63: BrandE | L63: 1 | M63: 2534.47 | N63: 5 | O63: 2407.75
A64: 10350 | B64: 1640 | C64: 45180 | D64: 45185 | E64: Chennai | F64: Telangana | G64: Mobile App | H64: UPI | I64: Books | J64: Textbook | K64: BrandA | L64: 1 | M64: 3708.38 | N64: 20 | O64: 2966.7
A65: 10018 | B65: 1871 | C65: 45045 | D65: 45048 | E65: Chennai | F65: West Bengal | G65: Website | H65: Credit Card | I65: Home & Kitchen | J65: Curtains | K65: BrandD | L65: 1 | M65: 2165.81 | N65: 15 | O65: 1840.94
A66: 10065 | B66: 1273 | C66: 45054 | D66: 45058 | E66: Chennai | F66: Karnataka | G66: Mobile App | H66: Net Banking | I66: Home & Kitchen | J66: Bedsheet | K66: BrandC | L66: 2 | M66: 2773.21 | N66: 10 | O66: 4991.78
A67: 10261 | B67: 1826 | C67: 44933 | D67: 44936 | E67: Chennai | F67: Maharashtra | G67: Website | H67: Debit Card | I67: Fashion | J67: Sneakers | K67: BrandE | L67: 2 | M67: 533.25 | N67: 0 | O67: 1066.5
A68: 10285 | B68: 1001 | C68: 45104 | D68: 45109 | E68: Chennai | F68: Tamil Nadu | G68: Mobile App | H68: UPI | I68: Beauty | J68: Lipstick | K68: BrandA | L68: 2 | M68: 702.07 | N68: 10 | O68: 1263.73
A69: 10332 | B69: 1954 | C69: 44946 | D69: 44955 | E69: Chennai | F69: Tamil Nadu | G69: Mobile App | H69: Net Banking | I69: Books | J69: Biography | K69: BrandA | L69: 2 | M69: 1335.36 | N69: 5 | O69: 2537.18
A70: 10386 | B70: 1119 | C70: 45146 | D70: 45154 | E70: Chennai | F70: Tamil Nadu | G70: Website | H70: UPI | I70: Electronics | J70: Smartphone | K70: BrandD | L70: 2 | M70: 1984.38 | N70: 10 | O70: 3571.88
A71: 10108 | B71: 1815 | C71: 45037 | D71: 45045 | E71: Chennai | F71: West Bengal | G71: Website | H71: Credit Card | I71: Sports | J71: Yoga Mat | K71: BrandA | L71: 2 | M71: 564.31 | N71: 15 | O71: 959.33
A72: 10192 | B72: 1891 | C72: 45039 | D72: 45042 | E72: Chennai | F72: West Bengal | G72: Marketplace | H72: Cash on Delivery | I72: Beauty | J72: Perfume | K72: BrandA | L72: 2 | M72: 487.23 | N72: 15 | O72: 828.29
... A501: 10407 | B501: 1877 | C501: 45088 | D501: 45090 | E501: Pune | F501: Tamil Nadu | G501: Website | H501: Debit Card | I501: Beauty | J501: Shampoo | K501: BrandE | L501: 9 | M501: 3216.56 | N501: 20 | O501: 23159.23

Sheet Day4 01.10.2026 s&f1
A1: Payment Method | C1: Order ID | D1: Customer ID | E1: Order Date | F1: Ship Date | G1: City | H1: State | I1: Sales Channel | J1: Payment Method | K1: Product Category | L1: Product Name | M1: Brand | N1: Units Sold | O1: Unit Price | P1: Discount % | Q1: Net Sales
A2: Debit Card | C2: 10045 | D2: 1699 | E2: 45139 | F2: 45147 | G2: Bengaluru | H2: Delhi | I2: Mobile App | J2: Debit Card | K2: Sports | L2: Cricket Bat | M2: BrandB | N2: 1 | O2: 2764.92 | P2: 0 | Q2: 2764.92
C3: 10317 | D3: 1981 | E3: 45051 | F3: 45056 | G3: Bengaluru | H3: Karnataka | I3: Website | J3: Debit Card | K3: Electronics | L3: Laptop | M3: BrandB | N3: 2 | O3: 788.72 | P3: 20 | Q3: 1261.95
C4: 10190 | D4: 1857 | E4: 45185 | F4: 45187 | G4: Bengaluru | H4: Maharashtra | I4: Marketplace | J4: Debit Card | K4: Electronics | L4: Smartwatch | M4: BrandA | N4: 2 | O4: 1372.59 | P4: 5 | Q4: 2607.92
C5: 10224 | D5: 1795 | E5: 45100 | F5: 45106 | G5: Bengaluru | H5: Tamil Nadu | I5: Marketplace | J5: Debit Card | K5: Books | L5: Fiction Novel | M5: BrandA | N5: 2 | O5: 1448.65 | P5: 20 | Q5: 2317.84
C6: 10194 | D6: 1690 | E6: 45180 | F6: 45182 | G6: Bengaluru | H6: Telangana | I6: Website | J6: Debit Card | K6: Books | L6: Comics | M6: BrandC | N6: 2 | O6: 894.01 | P6: 15 | Q6: 1519.82
C7: 10239 | D7: 1384 | E7: 45146 | F7: 45149 | G7: Bengaluru | H7: Telangana | I7: Website | J7: Debit Card | K7: Electronics | L7: Laptop | M7: BrandB | N7: 2 | O7: 3960.56 | P7: 10 | Q7: 7129.01
C8: 10176 | D8: 1942 | E8: 45166 | F8: 45168 | G8: Bengaluru | H8: West Bengal | I8: Marketplace | J8: Debit Card | K8: Fashion | L8: Jacket | M8: BrandC | N8: 5 | O8: 1551.83 | P8: 5 | Q8: 7371.19
C9: 10159 | D9: 1929 | E9: 45109 | F9: 45113 | G9: Bengaluru | H9: Delhi | I9: Website | J9: Debit Card | K9: Electronics | L9: Smartphone | M9: BrandC | N9: 6 | O9: 3800.77 | P9: 0 | Q9: 22804.62
C10: 10034 | D10: 1313 | E10: 45182 | F10: 45191 | G10: Bengaluru | H10: Tamil Nadu | I10: Marketplace | J10: Debit Card | K10: Fashion | L10: T-Shirt | M10: BrandB | N10: 6 | O10: 1529.59 | P10: 0 | Q10: 9177.54
C11: 10349 | D11: 1871 | E11: 45174 | F11: 45177 | G11: Bengaluru | H11: West Bengal | I11: Marketplace | J11: Debit Card | K11: Home & Kitchen | L11: Curtains | M11: BrandB | N11: 6 | O11: 3281.72 | P11: 5 | Q11: 18705.8
C12: 10482 | D12: 1606 | E12: 45153 | F12: 45162 | G12: Bengaluru | H12: Maharashtra | I12: Website | J12: Debit Card | K12: Books | L12: Biography | M12: BrandE | N12: 7 | O12: 2172.24 | P12: 20 | Q12: 12164.54
C13: 10454 | D13: 1959 | E13: 45251 | F13: 45255 | G13: Bengaluru | H13: Telangana | I13: Mobile App | J13: Debit Card | K13: Books | L13: Fiction Novel | M13: BrandD | N13: 9 | O13: 3191.56 | P13: 20 | Q13: 22979.23
C14: 10261 | D14: 1826 | E14: 44933 | F14: 44936 | G14: Chennai | H14: Maharashtra | I14: Website | J14: Debit Card | K14: Fashion | L14: Sneakers | M14: BrandE | N14: 2 | O14: 533.25 | P14: 0 | Q14: 1066.5
... C88: 10407 | D88: 1877 | E88: 45088 | F88: 45090 | G88: Pune | H88: Tamil Nadu | I88: Website | J88: Debit Card | K88: Beauty | L88: Shampoo | M88: BrandE | N88: 9 | O88: 3216.56 | P88: 20 | Q88: 23159.23

Sheet Day5 05.10.2026
A1: Order ID | B1: Customer ID | C1: Order Date | D1: Ship Date | E1: City | F1: State | G1: Sales Channel | H1: Payment Method | I1: Product Category | J1: Product Name | K1: Brand | L1: Units Sold | M1: Unit Price | N1: Discount % | O1: Net Sales | Q1: Sales Channel | T1: Sales Channel
A2: 10001 | B2: 1102 | C2: 45197 | D2: 45203 | E2: Chennai | F2: Delhi | G2: Mobile App | H2: Credit Card | I2: Home & Kitchen | J2: Mixer Grinder | K2: BrandA | L2: 7 | M2: 2843.87 | N2: 0 | O2: 19907.09 | Q2: Marketplace | T2: Mobile App
A3: 10002 | B3: 1435 | C3: 45199 | D3: 45203 | E3: Pune | F3: Tamil Nadu | G3: Website | H3: Debit Card | I3: Sports | J3: Football | K3: BrandD | L3: 9 | M3: 2525.23 | N3: 5 | O3: 21590.72 | T3: Website
A4: 10003 | B4: 1860 | C4: 45109 | D4: 45114 | E4: Chennai | F4: West Bengal | G4: Marketplace | H4: Debit Card | I4: Fashion | J4: Sneakers | K4: BrandE | L4: 6 | M4: 3474.34 | N4: 15 | O4: 17719.13 | T4: Marketplace
A5: 10004 | B5: 1270 | C5: 45079 | D5: 45087 | E5: Bengaluru | F5: West Bengal | G5: Website | H5: Cash on Delivery | I5: Sports | J5: Yoga Mat | K5: BrandA | L5: 1 | M5: 1008.79 | N5: 15 | O5: 857.47
A6: 10005 | B6: 1106 | C6: 45241 | D6: 45244 | E6: Kolkata | F6: Karnataka | G6: Marketplace | H6: Credit Card | I6: Fashion | J6: Jacket | K6: BrandA | L6: 7 | M6: 3511.47 | N6: 20 | O6: 19664.23
A7: 10006 | B7: 1071 | C7: 45260 | D7: 45263 | E7: Hyderabad | F7: Telangana | G7: Website | H7: Net Banking | I7: Home & Kitchen | J7: Bedsheet | K7: BrandE | L7: 3 | M7: 3189.55 | N7: 10 | O7: 8611.78
A8: 10007 | B8: 1700 | C8: 45050 | D8: 45054 | E8: Bengaluru | F8: Telangana | G8: Mobile App | H8: UPI | I8: Fashion | J8: Sneakers | K8: BrandC | L8: 5 | M8: 3030.42 | N8: 10 | O8: 13636.89
A9: 10008 | B9: 1020 | C9: 45040 | D9: 45041 | E9: Mumbai | F9: Delhi | G9: Website | H9: Credit Card | I9: Fashion | J9: Sneakers | K9: BrandB | L9: 4 | M9: 2310.83 | N9: 10 | O9: 8318.99
A10: 10009 | B10: 1614 | C10: 45204 | D10: 45213 | E10: Chennai | F10: West Bengal | G10: Website | H10: Debit Card | I10: Fashion | J10: T-Shirt | K10: BrandD | L10: 5 | M10: 1098.04 | N10: 15 | O10: 4666.67
A11: 10010 | B11: 1121 | C11: 45139 | D11: 45147 | E11: Bengaluru | F11: Karnataka | G11: Website | H11: Cash on Delivery | I11: Electronics | J11: Headphones | K11: BrandB | L11: 5 | M11: 1780.66 | N11: 20 | O11: 7122.64
A12: 10011 | B12: 1466 | C12: 45098 | D12: 45106 | E12: Bengaluru | F12: Karnataka | G12: Mobile App | H12: Cash on Delivery | I12: Electronics | J12: Headphones | K12: BrandE | L12: 6 | M12: 3205.25 | N12: 0 | O12: 19231.5
A13: 10012 | B13: 1214 | C13: 45214 | D13: 45220 | E13: Mumbai | F13: Tamil Nadu | G13: Website | H13: UPI | I13: Electronics | J13: Smartwatch | K13: BrandA | L13: 6 | M13: 272.35 | N13: 5 | O13: 1552.39
A14: 10013 | B14: 1330 | C14: 45100 | D14: 45107 | E14: Delhi | F14: Tamil Nadu | G14: Mobile App | H14: Cash on Delivery | I14: Home & Kitchen | J14: Bedsheet | K14: BrandA | L14: 8 | M14: 3160.9 | N14: 0 | O14: 25287.2
A15: 10014 | B15: 1458 | C15: 45039 | D15: 45045 | E15: Kolkata | F15: Karnataka | G15: Marketplace | H15: Cash on Delivery | I15: Sports | J15: Yoga Mat | K15: BrandD | L15: 8 | M15: 1074.27 | N15: 15 | O15: 7305.04
A16: 10015 | B16: 1087 | C16: 45048 | D16: 45057 | E16: Hyderabad | F16: Tamil Nadu | G16: Website | H16: Credit Card | I16: Beauty | J16: Shampoo | K16: BrandA | L16: 9 | M16: 705.59 | N16: 10 | O16: 5715.28
... A501: 10500 | B501: 1569 | C501: 44972 | D501: 44977 | E501: Chennai | F501: Delhi | G501: Marketplace | H501: Net Banking | I501: Fashion | J501: Jeans | K501: BrandE | L501: 1 | M501: 2432.17 | N501: 20 | O501: 1945.74

Sheet Day6.10.26 Flashfill,Text fr. 
A1: Order ID | B1: Customer ID | C1: Order Date | D1: Ship Date | E1: City | F1: State | G1: Sales Channel | H1: Payment Method | I1: Product Category | J1: Product Name | K1: Brand | L1: Units Sold | M1: Unit Price | N1: Discount % | O1: Net Sales | P1: Brand FLASH FILL Using (CTRL+E) | Q1: Right Values | R1: Middle Values | S1: Len of productname | T1: Trim | U1: Len | V1: upper | W1: lower | X1: proper | Y1: concat | Z1: concat using range | AA1: concatenate | AB1: Text Join | AC1: find the position | AD1: search | AE1: replace | AF1: text split
A2: 10001 | B2: 1102 | C2: 45197 | D2: 45203 | E2: Chennai | F2: Delhi | G2: Mobile App | H2: Credit Card | I2: Home & Kitchen | J2: Mixer Grinder | K2: BrandA | L2: 7 | M2: 2843.87 | N2: 0 | O2: 19907.09 | P2: BrandA | Q2: =RIGHT(H2,3) -> ard | R2: =MID(J2,2,4) -> ixer | S2: =LEN(J2) -> 16 | T2: =TRIM(J2) -> Mixer Grinder | U2: =LEN(T2) -> 13 | V2: =UPPER(T2) -> MIXER GRINDER | W2: =LOWER(V2) -> mixer grinder | X2: =PROPER(W2) -> Mixer Grinder | Y2: =_xlfn.CONCAT(F2," ",L2) -> Delhi 7 | Z2: =_xlfn.CONCAT(K2:L2) -> BrandA7 | AA2: =CONCATENATE(K2," ",L2) -> BrandA 7 | AB2: =_xlfn.TEXTJOIN(" ",TRUE,F2:G2) -> Delhi Mobile App | AC2: =FIND("e",G2) -> 6 | AD2: =SEARCH("M",AB2) -> 7 | AE2: =REPLACE(AB2,5,3,"p") -> Delhpobile App | AF2: delhi | AG2: mobile | AH2: app
A3: 10002 | B3: 1435 | C3: 45199 | D3: 45203 | E3: Pune | F3: Tamil Nadu | G3: Website | H3: Debit Card | I3: Sports | J3: Football | K3: BrandD | L3: 9 | M3: 2525.23 | N3: 5 | O3: 21590.72 | P3: BrandD | Q3: =RIGHT(H3,3) -> ard | R3: =MID(J3,2,4) -> ootb | S3: =LEN(J3) -> 12 | T3: =TRIM(J3) -> Football | U3: =LEN(T3) -> 8 | V3: =UPPER(T3) -> FOOTBALL | W3: =LOWER(V3) -> football | X3: =PROPER(W3) -> Football | Y3: =_xlfn.CONCAT(F3," ",L3) -> Tamil Nadu 9 | Z3: =_xlfn.CONCAT(K3:L3) -> BrandD9 | AA3: =CONCATENATE(K3," ",L3) -> BrandD 9 | AB3: =_xlfn.TEXTJOIN(" ",TRUE,F3:G3) -> Tamil Nadu Website | AC3: =FIND("e",G3) -> 2 | AD3: =SEARCH("M",AB3) -> 3 | AE3: =REPLACE(AB3,5,3,"p") -> Tamipadu Website | AF3: tamil nadu | AG3: website | AH3: website
A4: 10003 | B4: 1860 | C4: 45109 | D4: 45114 | E4: Chennai | F4: West Bengal | G4: Marketplace | H4: Debit Card | I4: Fashion | J4: Sneakers | K4: BrandE | L4: 6 | M4: 3474.34 | N4: 15 | O4: 17719.13 | P4: BrandE | Q4: =RIGHT(H4,3) -> ard | R4: =MID(J4,2,4) -> S | S4: =LEN(J4) -> 12 | T4: =TRIM(J4) -> Sneakers | U4: =LEN(T4) -> 8 | V4: =UPPER(T4) -> SNEAKERS | W4: =LOWER(V4) -> sneakers | X4: =PROPER(W4) -> Sneakers | Y4: =_xlfn.CONCAT(F4," ",L4) -> West Bengal 6 | Z4: =_xlfn.CONCAT(K4:L4) -> BrandE6 | AA4: =CONCATENATE(K4," ",L4) -> BrandE 6 | AB4: =_xlfn.TEXTJOIN(" ",TRUE,F4:G4) -> West Bengal Marketplace | AC4: =FIND("e",G4) -> 5 | AD4: =SEARCH("M",AB4) -> 13 | AE4: =REPLACE(AB4,5,3,"p") -> Westpngal Marketplace | AF4: west bengal | AG4: marketplace | AH4: marketplace
A5: 10004 | B5: 1270 | C5: 45079 | D5: 45087 | E5: Bengaluru | F5: West Bengal | G5: Website | H5: Cash on Delivery | I5: Sports | J5: Yoga Mat | K5: BrandA | L5: 1 | M5: 1008.79 | N5: 15 | O5: 857.47 | P5: BrandA | Q5: =RIGHT(H5,3) -> ery | R5: =MID(J5,2,4) -> oga | S5: =LEN(J5) -> 8 | T5: =TRIM(J5) -> Yoga Mat | U5: =LEN(T5) -> 8 | V5: =UPPER(T5) -> YOGA MAT | W5: =LOWER(V5) -> yoga mat | X5: =PROPER(W5) -> Yoga Mat | Y5: =_xlfn.CONCAT(F5," ",L5) -> West Bengal 1 | Z5: =_xlfn.CONCAT(K5:L5) -> BrandA1 | AA5: =CONCATENATE(K5," ",L5) -> BrandA 1 | AB5: =_xlfn.TEXTJOIN(" ",TRUE,F5:G5) -> West Bengal Website | AC5: =FIND("e",G5) -> 2 | AD5: =SEARCH("M",AB5) -> #VALUE! | AE5: =REPLACE(AB5,5,3,"p") -> Westpngal Website | AF5: west bengal | AG5: website | AH5: website
A6: 10005 | B6: 1106 | C6: 45241 | D6: 45244 | E6: Kolkata | F6: Karnataka | G6: Marketplace | H6: Credit Card | I6: Fashion | J6: Jacket | K6: BrandA | L6: 7 | M6: 3511.47 | N6: 20 | O6: 19664.23 | P6: BrandA | Q6: =RIGHT(H6,3) -> ard | R6: =MID(J6,2,4) -> acke | S6: =LEN(J6) -> 6 | T6: =TRIM(J6) -> Jacket | U6: =LEN(T6) -> 6 | V6: =UPPER(T6) -> JACKET | W6: =LOWER(V6) -> jacket | X6: =PROPER(W6) -> Jacket | Y6: =_xlfn.CONCAT(F6," ",L6) -> Karnataka 7 | Z6: =_xlfn.CONCAT(K6:L6) -> BrandA7 | AA6: =CONCATENATE(K6," ",L6) -> BrandA 7 | AB6: =_xlfn.TEXTJOIN(" ",TRUE,F6:G6) -> Karnataka Marketplace | AC6: =FIND("e",G6) -> 5 | AD6: =SEARCH("M",AB6) -> 11 | AE6: =REPLACE(AB6,5,3,"p") -> Karnpka Marketplace | AF6: karnataka | AG6: marketplace | AH6: marketplace
A7: 10006 | B7: 1071 | C7: 45260 | D7: 45263 | E7: Hyderabad | F7: Telangana | G7: Website | H7: Net Banking | I7: Home & Kitchen | J7: Bedsheet | K7: BrandE | L7: 3 | M7: 3189.55 | N7: 10 | O7: 8611.78 | P7: BrandE | Q7: =RIGHT(H7,3) -> ing | R7: =MID(J7,2,4) -> edsh | S7: =LEN(J7) -> 8 | T7: =TRIM(J7) -> Bedsheet | U7: =LEN(T7) -> 8 | V7: =UPPER(T7) -> BEDSHEET | W7: =LOWER(V7) -> bedsheet | X7: =PROPER(W7) -> Bedsheet | Y7: =_xlfn.CONCAT(F7," ",L7) -> Telangana 3 | Z7: =_xlfn.CONCAT(K7:L7) -> BrandE3 | AA7: =CONCATENATE(K7," ",L7) -> BrandE 3 | AB7: =_xlfn.TEXTJOIN(" ",TRUE,F7:G7) -> Telangana Website | AC7: =FIND("e",G7) -> 2 | AD7: =SEARCH("M",AB7) -> #VALUE! | AE7: =REPLACE(AB7,5,3,"p") -> Telapna Website | AF7: telangana | AG7: website | AH7: website
A8: 10007 | B8: 1700 | C8: 45050 | D8: 45054 | E8: Bengaluru | F8: Telangana | G8: Mobile App | H8: UPI | I8: Fashion | J8: Sneakers | K8: BrandC | L8: 5 | M8: 3030.42 | N8: 10 | O8: 13636.89 | P8: BrandC | Q8: =RIGHT(H8,3) -> UPI | R8: =MID(J8,2,4) -> neak | S8: =LEN(J8) -> 8 | T8: =TRIM(J8) -> Sneakers | U8: =LEN(T8) -> 8 | V8: =UPPER(T8) -> SNEAKERS | W8: =LOWER(V8) -> sneakers | X8: =PROPER(W8) -> Sneakers | Y8: =_xlfn.CONCAT(F8," ",L8) -> Telangana 5 | Z8: =_xlfn.CONCAT(K8:L8) -> BrandC5 | AA8: =CONCATENATE(K8," ",L8) -> BrandC 5 | AB8: =_xlfn.TEXTJOIN(" ",TRUE,F8:G8) -> Telangana Mobile App | AC8: =FIND("e",G8) -> 6 | AD8: =SEARCH("M",AB8) -> 11 | AE8: =REPLACE(AB8,5,3,"p") -> Telapna Mobile App | AF8: telangana | AG8: mobile | AH8: app
A9: 10008 | B9: 1020 | C9: 45040 | D9: 45041 | E9: Mumbai | F9: Delhi | G9: Website | H9: Credit Card | I9: Fashion | J9: Sneakers | K9: BrandB | L9: 4 | M9: 2310.83 | N9: 10 | O9: 8318.99 | P9: BrandB | Q9: =RIGHT(H9,3) -> ard | R9: =MID(J9,2,4) -> neak | S9: =LEN(J9) -> 8 | T9: =TRIM(J9) -> Sneakers | U9: =LEN(T9) -> 8 | V9: =UPPER(T9) -> SNEAKERS | W9: =LOWER(V9) -> sneakers | X9: =PROPER(W9) -> Sneakers | Y9: =_xlfn.CONCAT(F9," ",L9) -> Delhi 4 | Z9: =_xlfn.CONCAT(K9:L9) -> BrandB4 | AA9: =CONCATENATE(K9," ",L9) -> BrandB 4 | AB9: =_xlfn.TEXTJOIN(" ",TRUE,F9:G9) -> Delhi Website | AC9: =FIND("e",G9) -> 2 | AD9: =SEARCH("M",AB9) -> #VALUE! | AE9: =REPLACE(AB9,5,3,"p") -> Delhpebsite | AF9: delhi | AG9: website | AH9: website
A10: 10009 | B10: 1614 | C10: 45204 | D10: 45213 | E10: Chennai | F10: West Bengal | G10: Website | H10: Debit Card | I10: Fashion | J10: T-Shirt | K10: BrandD | L10: 5 | M10: 1098.04 | N10: 15 | O10: 4666.67 | P10: BrandD | Q10: =RIGHT(H10,3) -> ard | R10: =MID(J10,2,4) -> -Shi | S10: =LEN(J10) -> 7 | T10: =TRIM(J10) -> T-Shirt | U10: =LEN(T10) -> 7 | V10: =UPPER(T10) -> T-SHIRT | W10: =LOWER(V10) -> t-shirt | X10: =PROPER(W10) -> T-Shirt | Y10: =_xlfn.CONCAT(F10," ",L10) -> West Bengal 5 | Z10: =_xlfn.CONCAT(K10:L10) -> BrandD5 | AA10: =CONCATENATE(K10," ",L10) -> BrandD 5 | AB10: =_xlfn.TEXTJOIN(" ",TRUE,F10:G10) -> West Bengal Website | AC10: =FIND("e",G10) -> 2 | AD10: =SEARCH("M",AB10) -> #VALUE! | AE10: =REPLACE(AB10,5,3,"p") -> Westpngal Website | AF10: west bengal | AG10: website | AH10: website
A11: 10010 | B11: 1121 | C11: 45139 | D11: 45147 | E11: Bengaluru | F11: Karnataka | G11: Website | H11: Cash on Delivery | I11: Electronics | J11: Headphones | K11: BrandB | L11: 5 | M11: 1780.66 | N11: 20 | O11: 7122.64 | P11: BrandB | Q11: =RIGHT(H11,3) -> ery | R11: =MID(J11,2,4) -> eadp | S11: =LEN(J11) -> 10 | T11: =TRIM(J11) -> Headphones | U11: =LEN(T11) -> 10 | V11: =UPPER(T11) -> HEADPHONES | W11: =LOWER(V11) -> headphones | X11: =PROPER(W11) -> Headphones | Y11: =_xlfn.CONCAT(F11," ",L11) -> Karnataka 5 | Z11: =_xlfn.CONCAT(K11:L11) -> BrandB5 | AA11: =CONCATENATE(K11," ",L11) -> BrandB 5 | AB11: =_xlfn.TEXTJOIN(" ",TRUE,F11:G11) -> Karnataka Website | AC11: =FIND("e",G11) -> 2 | AD11: =SEARCH("M",AB11) -> #VALUE! | AE11: =REPLACE(AB11,5,3,"p") -> Karnpka Website | AF11: karnataka | AG11: website | AH11: website
A12: 10011 | B12: 1466 | C12: 45098 | D12: 45106 | E12: Bengaluru | F12: Karnataka | G12: Mobile App | H12: Cash on Delivery | I12: Electronics | J12: Headphones | K12: BrandE | L12: 6 | M12: 3205.25 | N12: 0 | O12: 19231.5 | P12: BrandE | Q12: =RIGHT(H12,3) -> ery | R12: =MID(J12,2,4) -> eadp | S12: =LEN(J12) -> 10 | T12: =TRIM(J12) -> Headphones | U12: =LEN(T12) -> 10 | V12: =UPPER(T12) -> HEADPHONES | W12: =LOWER(V12) -> headphones | X12: =PROPER(W12) -> Headphones | Y12: =_xlfn.CONCAT(F12," ",L12) -> Karnataka 6 | Z12: =_xlfn.CONCAT(K12:L12) -> BrandE6 | AA12: =CONCATENATE(K12," ",L12) -> BrandE 6 | AB12: =_xlfn.TEXTJOIN(" ",TRUE,F12:G12) -> Karnataka Mobile App | AC12: =FIND("e",G12) -> 6 | AD12: =SEARCH("M",AB12) -> 11 | AE12: =REPLACE(AB12,5,3,"p") -> Karnpka Mobile App | AF12: karnataka | AG12: mobile | AH12: app
